Workbook
Name UPDATE: 'Data Sheet'!$E$1

Sheet Financials

Sheet Historical_FS
B2: ="Historical Financial Statement - " & 'Data Sheet'!B1 -> Historical Financial Statement - GODREJ CONSUMER PRODUCTS LTD
B3: Year | C3: ='Data Sheet'!B16 -> 42460 | D3: ='Data Sheet'!C16 -> 42825 | E3: ='Data Sheet'!D16 -> 43190 | F3: ='Data Sheet'!E16 -> 43555 | G3: ='Data Sheet'!F16 -> 43921 | H3: ='Data Sheet'!G16 -> 44286 | I3: ='Data Sheet'!H16 -> 44651 | J3: ='Data Sheet'!I16 -> 45016 | ... L3: ='Data Sheet'!K16 -> 45747 | M3: LTM
A5: # | B5: Income Statement
B6: Sale | C6: =IFERROR('Data Sheet'!B17,0) -> 8423.88 | D6: =IFERROR('Data Sheet'!C17,0) -> 9267.91 | E6: =IFERROR('Data Sheet'!D17,0) -> 9847.43 | F6: =IFERROR('Data Sheet'!E17,0) -> 10314.34 | G6: =IFERROR('Data Sheet'!F17,0) -> 9910.8 | H6: =IFERROR('Data Sheet'!G17,0) -> 11028.62 | I6: =IFERROR('Data Sheet'!H17,0) -> 12276.5 | J6: =IFERROR('Data Sheet'!I17,0) -> 13315.97 | ... L6: =IFERROR('Data Sheet'!K17,0) -> 14364.29 | M6: =IFERROR(SUM('Data Sheet'!H42:K42),0) -> 15184.02
B7: Sale Growth | C7: - | D7: =C6/D6-1 -> -0.091070155 | E7: =D6/E6-1 -> -0.058849873 | F7: =E6/F6-1 -> -0.045268044 | G7: =F6/G6-1 -> 0.040717197 | H7: =G6/H6-1 -> -0.10135629 | I7: =H6/I6-1 -> -0.10164786 | J7: =I6/J6-1 -> -0.078061906 | K7: =J6/K6-1 -> -0.055344347 | ... M7: =L6/M6-1 -> -0.053986362
B9: COGS | C9: =IFERROR(SUM('Data Sheet'!B18,'Data Sheet'!B20:B22)-1*'Data Sheet'!B19,0) -> 5157.59 | D9: =IFERROR(SUM('Data Sheet'!C18,'Data Sheet'!C20:C22)-1*'Data Sheet'!C19,0) -> 5512.85 | E9: =IFERROR(SUM('Data Sheet'!D18,'Data Sheet'!D20:D22)-1*'Data Sheet'!D19,0) -> 5751.63 | F9: =IFERROR(SUM('Data Sheet'!E18,'Data Sheet'!E20:E22)-1*'Data Sheet'!E19,0) -> 6071.83 | G9: =IFERROR(SUM('Data Sheet'!F18,'Data Sheet'!F20:F22)-1*'Data Sheet'!F19,0) -> 5777.48 | H9: =IFERROR(SUM('Data Sheet'!G18,'Data Sheet'!G20:G22)-1*'Data Sheet'!G19,0) -> 6556.24 | I9: =IFERROR(SUM('Data Sheet'!H18,'Data Sheet'!H20:H22)-1*'Data Sheet'!H19,0) -> 7743.02 | J9: =IFERROR(SUM('Data Sheet'!I18,'Data Sheet'!I20:I22)-1*'Data Sheet'!I19,0) -> 8407.81 | ... L9: =IFERROR(SUM('Data Sheet'!K18,'Data Sheet'!K20:K22)-1*'Data Sheet'!K19,0) -> 8273.17 | M9: =IFERROR(SUM('Data Sheet'!H43:K43),0) -> 12116.47
B10: COGS % Sales | C10: =C9/C6 -> 0.61225825 | D10: =D9/D6 -> 0.59483206 | E10: =E9/E6 -> 0.58407422 | F10: =F9/F6 -> 0.58867848 | G10: =G9/G6 -> 0.5829479 | H10: =H9/H6 -> 0.5944751 | I10: =I9/I6 -> 0.63071885 | J10: =J9/J6 -> 0.631408 | ... M10: =M9/M6 -> 0.79797511
B12: Gross Profit | C12: =C6-C9 -> 3266.29 | D12: =D6-D9 -> 3755.06 | E12: =E6-E9 -> 4095.8 | F12: =F6-F9 -> 4242.51 | G12: =G6-G9 -> 4133.32 | H12: =H6-H9 -> 4472.38 | I12: =I6-I9 -> 4533.48 | J12: =J6-J9 -> 4908.16 | ... M12: =M6-M9 -> 3067.55
B13: Gross Margins | C13: =C12/C6 -> 0.38774175 | D13: =D12/D6 -> 0.40516794 | E13: =E12/E6 -> 0.41592578 | F13: =F12/F6 -> 0.41132152 | G13: =G12/G6 -> 0.4170521 | H13: =H12/H6 -> 0.4055249 | I13: =I12/I6 -> 0.36928115 | J13: =J12/J6 -> 0.368592 | ... M13: =M12/M6 -> 0.20202489
B15: Selling & General Expenses | C15: =IFERROR(SUM('Data Sheet'!B23:B24),0) -> 1608.91 | D15: =IFERROR(SUM('Data Sheet'!C23:C24),0) -> 1848.35 | E15: =IFERROR(SUM('Data Sheet'!D23:D24),0) -> 2011.4 | F15: =IFERROR(SUM('Data Sheet'!E23:E24),0) -> 2110.94 | G15: =IFERROR(SUM('Data Sheet'!F23:F24),0) -> 1979.57 | H15: =IFERROR(SUM('Data Sheet'!G23:G24),0) -> 2073.12 | I15: =IFERROR(SUM('Data Sheet'!H23:H24),0) -> 2124.3 | J15: =IFERROR(SUM('Data Sheet'!I23:I24),0) -> 2464.96 | ... L15: =IFERROR(SUM('Data Sheet'!K23:K24),0) -> 3076.11
B16: S&G Expenses % sales | C16: =C15/C6 -> 0.19099394 | D16: =D15/D6 -> 0.19943547 | E16: =E15/E6 -> 0.20425634 | F16: =F15/F6 -> 0.2046607 | G16: =G15/G6 -> 0.19973867 | H16: =H15/H6 -> 0.18797637 | I16: =I15/I6 -> 0.17303792 | J16: =J15/J6 -> 0.18511306 | ... M16: =M15/M6 -> 0
B18: EBITDA | C18: =C12-C15 -> 1657.38 | D18: =D12-D15 -> 1906.71 | E18: =E12-E15 -> 2084.4 | F18: =F12-F15 -> 2131.57 | G18: =G12-G15 -> 2153.75 | H18: =H12-H15 -> 2399.26 | I18: =I12-I15 -> 2409.18 | J18: =J12-J15 -> 2443.2 | ... M18: =M12-M15 -> 3067.55
B19: EBITDA Margins | C19: =C18/C6 -> 0.19674782 | D19: =D18/D6 -> 0.20573247 | E19: =E18/E6 -> 0.21166944 | F19: =F18/F6 -> 0.20666082 | G19: =G18/G6 -> 0.21731344 | H19: =H18/H6 -> 0.21754852 | I19: =I18/I6 -> 0.19624323 | J19: =J18/J6 -> 0.18347894 | ... M19: =M18/M6 -> 0.20202489
B21: Interest | C21: =IFERROR('Data Sheet'!B25,0) -> -262.04 | D21: =IFERROR('Data Sheet'!C25,0) -> 76.18 | E21: =IFERROR('Data Sheet'!D25,0) -> 283.28 | F21: =IFERROR('Data Sheet'!E25,0) -> 361.95 | G21: =IFERROR('Data Sheet'!F25,0) -> 32.06 | H21: =IFERROR('Data Sheet'!G25,0) -> 22.6 | I21: =IFERROR('Data Sheet'!H25,0) -> 78.27 | J21: =IFERROR('Data Sheet'!I25,0) -> 114.3 | ... L21: =IFERROR('Data Sheet'!K25,0) -> 251.93 | M21: =IFERROR(SUM('Data Sheet'!H46:K46),0) -> 330.86
B22: Interest % Sales | C22: =C21/C6 -> -0.031106806 | D22: =D21/D6 -> 0.0082197604 | E22: =E21/E6 -> 0.028766897 | F22: =F21/F6 -> 0.035091921 | G22: =G21/G6 -> 0.0032348549 | H22: =H21/H6 -> 0.0020492138 | I22: =I21/I6 -> 0.0063755957 | J22: =J21/J6 -> 0.0085836781 | ... M22: =M21/M6 -> 0.021790013
B24: Depreciation | C24: =IFERROR('Data Sheet'!B26,0) -> 100.63 | D24: =IFERROR('Data Sheet'!C26,0) -> 141.57 | E24: =IFERROR('Data Sheet'!D26,0) -> 155.68 | F24: =IFERROR('Data Sheet'!E26,0) -> 169.98 | G24: =IFERROR('Data Sheet'!F26,0) -> 197.28 | H24: =IFERROR('Data Sheet'!G26,0) -> 203.85 | I24: =IFERROR('Data Sheet'!H26,0) -> 209.93 | J24: =IFERROR('Data Sheet'!I26,0) -> 236.29 | ... L24: =IFERROR('Data Sheet'!K26,0) -> 234 | M24: =IFERROR(SUM('Data Sheet'!H45:K45),0) -> 263.95
B25: Depreciation%Sales | C25: =C24/C6 -> 0.011945802 | D25: =D24/D6 -> 0.015275289 | E25: =E24/E6 -> 0.015809201 | F25: =F24/F6 -> 0.016479969 | G25: =G24/G6 -> 0.019905558 | H25: =H24/H6 -> 0.018483727 | I25: =I24/I6 -> 0.017100151 | J25: =J24/J6 -> 0.017744858 | ... M25: =M24/M6 -> 0.017383407
B27: Earnings Before Tax | C27: =IFERROR('Data Sheet'!B18-SUM('Data Sheet'!B24,B21),0) -> 3815.21 | D27: =IFERROR('Data Sheet'!C18-SUM('Data Sheet'!C24,C21),0) -> 4328.93 | E27: =IFERROR('Data Sheet'!D18-SUM('Data Sheet'!D24,D21),0) -> 3906.54 | F27: =IFERROR('Data Sheet'!E18-SUM('Data Sheet'!E24,E21),0) -> 3894.43 | G27: =IFERROR('Data Sheet'!F18-SUM('Data Sheet'!F24,F21),0) -> 3863.44 | H27: =IFERROR('Data Sheet'!G18-SUM('Data Sheet'!G24,G21),0) -> 4675.32 | I27: =IFERROR('Data Sheet'!H18-SUM('Data Sheet'!H24,H21),0) -> 5826.22 | J27: =IFERROR('Data Sheet'!I18-SUM('Data Sheet'!I24,I21),0) -> 6091.06 | ... L27: =IFERROR('Data Sheet'!K18-SUM('Data Sheet'!K24,K21),0) -> 9967.95 | M27: =IFERROR('Data Sheet'!M18-SUM('Data Sheet'!M4,M21),0) -> -330.86
B28: EBT % Sales | C28: =C27/C6 -> 0.45290412 | D28: =D27/D6 -> 0.46708805 | E28: =E27/E6 -> 0.39670655 | F28: =F27/F6 -> 0.37757433 | G28: =G27/G6 -> 0.38982121 | H28: =H27/H6 -> 0.42392611 | I28: =I27/I6 -> 0.47458315 | J28: =J27/J6 -> 0.45742518 | ... M28: =M27/M6 -> -0.021790013
B30: Tax | C30: =IFERROR('Data Sheet'!B29,0) -> 336.05 | D30: =IFERROR('Data Sheet'!C29,0) -> 379.16 | E30: =IFERROR('Data Sheet'!D29,0) -> 404.7 | F30: =IFERROR('Data Sheet'!E29,0) -> -256.2 | G30: =IFERROR('Data Sheet'!F29,0) -> 263.82 | H30: =IFERROR('Data Sheet'!G29,0) -> 359.54 | I30: =IFERROR('Data Sheet'!H29,0) -> 371.87 | J30: =IFERROR('Data Sheet'!I29,0) -> 430.27 | ... L30: =IFERROR('Data Sheet'!K29,0) -> 819.59 | M30: =IFERROR(SUM('Data Sheet'!H48:K48),0) -> 756.5
B31: Effective Tax Rate | C31: =C30/C27 -> 0.088081652 | D31: =D30/D27 -> 0.087587464 | E31: =E30/E27 -> 0.10359551 | F31: =F30/F27 -> -0.065786264 | G31: =G30/G27 -> 0.068286294 | H31: =H30/H27 -> 0.076901688 | I31: =I30/I27 -> 0.063826975 | J31: =J30/J27 -> 0.070639593 | ... M31: =M30/M27 -> -2.2864656
B33: Net Profit | C33: =IFERROR(C27-C30,0) -> 3479.16 | D33: =IFERROR(D27-D30,0) -> 3949.77 | E33: =IFERROR(E27-E30,0) -> 3501.84 | F33: =IFERROR(F27-F30,0) -> 4150.63 | G33: =IFERROR(G27-G30,0) -> 3599.62 | H33: =IFERROR(H27-H30,0) -> 4315.78 | I33: =IFERROR(I27-I30,0) -> 5454.35 | J33: =IFERROR(J27-J30,0) -> 5660.79 | ... M33: =IFERROR(M27-M30,0) -> -1087.36
B34: Net Margins | C34: =C33/C6 -> 0.41301158 | D34: =D33/D6 -> 0.42617699 | E34: =E33/E6 -> 0.35560953 | F34: =F33/F6 -> 0.40241353 | G34: =G33/G6 -> 0.36320176 | H34: =H33/H6 -> 0.39132548 | I34: =I33/I6 -> 0.44429194 | J34: =J33/J6 -> 0.42511285 | ... M34: =M33/M6 -> -0.071612129
B36: No of Equity Shares | C36: =IFERROR('Data Sheet'!E93,0) -> 102.22 | D36: =IFERROR('Data Sheet'!F93,0) -> 102.23 | E36: =IFERROR('Data Sheet'!G93,0) -> 102.25 | F36: =IFERROR('Data Sheet'!H93,0) -> 102.26 | G36: =IFERROR('Data Sheet'!I93,0) -> 102.27 | H36: =IFERROR('Data Sheet'!J93,0) -> 102.28 | I36: =IFERROR('Data Sheet'!K93,0) -> 102.3 | J36: =IFERROR('Data Sheet'!L93,0) -> 0 | ... L36: =IFERROR('Data Sheet'!N93,0) -> 0 | M36: =L36 -> 0
B38: Earnings Per Share | C38: =IFERROR(C33/C36,0) -> 34.036001 | D38: =IFERROR(D33/D36,0) -> 38.636115 | E38: =IFERROR(E33/E36,0) -> 34.247824 | F38: =IFERROR(F33/F36,0) -> 40.588989 | G38: =IFERROR(G33/G36,0) -> 35.197223 | H38: =IFERROR(H33/H36,0) -> 42.195737 | I38: =IFERROR(I33/I36,0) -> 53.317204 | J38: =IFERROR(J33/J36,0) -> 0 | ... M38: =IFERROR(M33/M36,0) -> 0
B39: EPS Growtn % | C39: - | D39: =IFERROR(D38/C38-1,0) -> 0.13515436 | E39: =IFERROR(E38/D38-1,0) -> -0.11358002 | F39: =IFERROR(F38/E38-1,0) -> 0.18515526 | G39: =IFERROR(G38/F38-1,0) -> -0.13283814 | H39: =IFERROR(H38/G38-1,0) -> 0.19883711 | I39: =IFERROR(I38/H38-1,0) -> 0.2635685 | J39: =IFERROR(J38/I38-1,0) -> -1 | K39: =IFERROR(K38/J38-1,0) -> 0 | ... M39: =IFERROR(M38/L38-1,0) -> 0
B41: Dividend per Share | C41: =IFERROR('Data Sheet'!E31/Historical_FS!C36,0) -> 10 | D41: =IFERROR('Data Sheet'!F31/Historical_FS!D36,0) -> 8 | E41: =IFERROR('Data Sheet'!G31/Historical_FS!E36,0) -> 0 | F41: =IFERROR('Data Sheet'!H31/Historical_FS!F36,0) -> 0 | G41: =IFERROR('Data Sheet'!I31/Historical_FS!G36,0) -> 0 | H41: =IFERROR('Data Sheet'!J31/Historical_FS!H36,0) -> 15 | I41: =IFERROR('Data Sheet'!K31/Historical_FS!I36,0) -> 25 | J41: =IFERROR('Data Sheet'!L31/Historical_FS!J36,0) -> 0 | ... M41: =IFERROR('Data Sheet'!O31/Historical_FS!M36,0) -> 0
B42: Dividend payout ratio | C42: =IFERROR(C41/C38,0) -> 0.29380655 | D42: =IFERROR(D41/D38,0) -> 0.20706016 | E42: =IFERROR(E41/E38,0) -> 0 | F42: =IFERROR(F41/F38,0) -> 0 | G42: =IFERROR(G41/G38,0) -> 0 | H42: =IFERROR(H41/H38,0) -> 0.35548615 | I42: =IFERROR(I41/I38,0) -> 0.4688918 | J42: =IFERROR(J41/J38,0) -> 0 | ... M42: =IFERROR(M41/M38,0) -> 0
B44: Retained Earnings | C44: =IFERROR(IF(C38>C41,1-C42,0),0) -> 0.70619345 | D44: =IFERROR(IF(D38>D41,1-D42,0),0) -> 0.79293984 | E44: =IFERROR(IF(E38>E41,1-E42,0),0) -> 1 | F44: =IFERROR(IF(F38>F41,1-F42,0),0) -> 1 | G44: =IFERROR(IF(G38>G41,1-G42,0),0) -> 1 | H44: =IFERROR(IF(H38>H41,1-H42,0),0) -> 0.64451385 | I44: =IFERROR(IF(I38>I41,1-I42,0),0) -> 0.5311082 | J44: =IFERROR(IF(J38>J41,1-J42,0),0) -> 0 | ... M44: =IFERROR(IF(M38>M41,1-M42,0),0) -> 0
A46: # | B46: Balance Sheet
B47: Equity Share Capital | C47: =IFERROR('Data Sheet'!B57,0) -> 34.05 | D47: =IFERROR('Data Sheet'!C57,0) -> 34.06 | E47: =IFERROR('Data Sheet'!D57,0) -> 68.13 | F47: =IFERROR('Data Sheet'!E57,0) -> 102.22 | G47: =IFERROR('Data Sheet'!F57,0) -> 102.23 | H47: =IFERROR('Data Sheet'!G57,0) -> 102.25 | I47: =IFERROR('Data Sheet'!H57,0) -> 102.26 | J47: =IFERROR('Data Sheet'!I57,0) -> 102.27 | ... L47: =IFERROR('Data Sheet'!K57,0) -> 102.3
B48: Reserves | C48: =IFERROR('Data Sheet'!B58,0) -> 4232.91 | D48: =IFERROR('Data Sheet'!C58,0) -> 5267.89 | E48: =IFERROR('Data Sheet'!D58,0) -> 6190.18 | F48: =IFERROR('Data Sheet'!E58,0) -> 7164.7 | G48: =IFERROR('Data Sheet'!F58,0) -> 7796.13 | H48: =IFERROR('Data Sheet'!G58,0) -> 9336.65 | I48: =IFERROR('Data Sheet'!H58,0) -> 11453.67 | J48: =IFERROR('Data Sheet'!I58,0) -> 13691.96 | ... L48: =IFERROR('Data Sheet'!K58,0) -> 11896.91
B49: Borrowings | C49: =IFERROR('Data Sheet'!B59,0) -> 2891.12 | D49: =IFERROR('Data Sheet'!C59,0) -> 4000.93 | E49: =IFERROR('Data Sheet'!D59,0) -> 3507.57 | F49: =IFERROR('Data Sheet'!E59,0) -> 3382.05 | G49: =IFERROR('Data Sheet'!F59,0) -> 3574.97 | H49: =IFERROR('Data Sheet'!G59,0) -> 1863.97 | I49: =IFERROR('Data Sheet'!H59,0) -> 1704.34 | J49: =IFERROR('Data Sheet'!I59,0) -> 1129.58 | ... L49: =IFERROR('Data Sheet'!K59,0) -> 4009.2
B50: Other Liabilities | C50: =IFERROR('Data Sheet'!B60,0) -> 2520.66 | D50: =IFERROR('Data Sheet'!C60,0) -> 3637.37 | E50: =IFERROR('Data Sheet'!D60,0) -> 4097.89 | F50: =IFERROR('Data Sheet'!E60,0) -> 3444.58 | G50: =IFERROR('Data Sheet'!F60,0) -> 3406.95 | H50: =IFERROR('Data Sheet'!G60,0) -> 2940.92 | I50: =IFERROR('Data Sheet'!H60,0) -> 2821.85 | J50: =IFERROR('Data Sheet'!I60,0) -> 2513.45 | ... L50: =IFERROR('Data Sheet'!K60,0) -> 3289.09
B51: Total liabilities | C51: =IFERROR('Data Sheet'!B61,0) -> 9678.74 | D51: =IFERROR('Data Sheet'!C61,0) -> 12940.25 | E51: =IFERROR('Data Sheet'!D61,0) -> 13863.77 | F51: =IFERROR('Data Sheet'!E61,0) -> 14093.55 | G51: =IFERROR('Data Sheet'!F61,0) -> 14880.28 | H51: =IFERROR('Data Sheet'!G61,0) -> 14243.79 | I51: =IFERROR('Data Sheet'!H61,0) -> 16082.12 | J51: =IFERROR('Data Sheet'!I61,0) -> 17437.26 | ... L51: =IFERROR('Data Sheet'!K61,0) -> 19297.5
B53: Fixed Assets Net Block | C53: =IFERROR('Data Sheet'!B62,0) -> 5931.41 | D53: =IFERROR('Data Sheet'!C62,0) -> 8082.89 | E53: =IFERROR('Data Sheet'!D62,0) -> 8315 | F53: =IFERROR('Data Sheet'!E62,0) -> 8670.26 | G53: =IFERROR('Data Sheet'!F62,0) -> 9231.4 | H53: =IFERROR('Data Sheet'!G62,0) -> 8904.77 | I53: =IFERROR('Data Sheet'!H62,0) -> 9219.3 | J53: =IFERROR('Data Sheet'!I62,0) -> 9933.66 | ... L53: =IFERROR('Data Sheet'!K62,0) -> 10676.19
B54: Capital Work in Progress | C54: =IFERROR('Data Sheet'!B63,0) -> 43.66 | D54: =IFERROR('Data Sheet'!C63,0) -> 97.43 | E54: =IFERROR('Data Sheet'!D63,0) -> 83.88 | F54: =IFERROR('Data Sheet'!E63,0) -> 52.06 | G54: =IFERROR('Data Sheet'!F63,0) -> 57.04 | H54: =IFERROR('Data Sheet'!G63,0) -> 57.43 | I54: =IFERROR('Data Sheet'!H63,0) -> 116.44 | J54: =IFERROR('Data Sheet'!I63,0) -> 45.42 | ... L54: =IFERROR('Data Sheet'!K63,0) -> 463.64
B55: Investments | C55: =IFERROR('Data Sheet'!B64,0) -> 189.5 | D55: =IFERROR('Data Sheet'!C64,0) -> 933.54 | E55: =IFERROR('Data Sheet'!D64,0) -> 997.28 | F55: =IFERROR('Data Sheet'!E64,0) -> 515.98 | G55: =IFERROR('Data Sheet'!F64,0) -> 671.98 | H55: =IFERROR('Data Sheet'!G64,0) -> 679.1 | I55: =IFERROR('Data Sheet'!H64,0) -> 1015.43 | J55: =IFERROR('Data Sheet'!I64,0) -> 3028.98 | ... L55: =IFERROR('Data Sheet'!K64,0) -> 3644.58
B56: Other Assets | C56: =IFERROR('Data Sheet'!B65-SUM('Data Sheet'!B67:B69),0) -> 335.39 | D56: =IFERROR('Data Sheet'!C65-SUM('Data Sheet'!C67:C69),0) -> 472.49 | E56: =IFERROR('Data Sheet'!D65-SUM('Data Sheet'!D67:D69),0) -> 684.18 | F56: =IFERROR('Data Sheet'!E65-SUM('Data Sheet'!E67:E69),0) -> 1109.04 | G56: =IFERROR('Data Sheet'!F65-SUM('Data Sheet'!F67:F69),0) -> 1289.33 | H56: =IFERROR('Data Sheet'!G65-SUM('Data Sheet'!G67:G69),0) -> 1209.53 | I56: =IFERROR('Data Sheet'!H65-SUM('Data Sheet'!H67:H69),0) -> 1377.01 | J56: =IFERROR('Data Sheet'!I65-SUM('Data Sheet'!I67:I69),0) -> 1256.05 | ... L56: =IFERROR('Data Sheet'!K65-SUM('Data Sheet'!K67:K69),0) -> 792.3
B57: Total Non Current Assets | C57: =SUM(C53:C56) -> 6499.96 | D57: =SUM(D53:D56) -> 9586.35 | E57: =SUM(E53:E56) -> 10080.34 | F57: =SUM(F53:F56) -> 10347.34 | G57: =SUM(G53:G56) -> 11249.75 | H57: =SUM(H53:H56) -> 10850.83 | I57: =SUM(I53:I56) -> 11728.18 | J57: =SUM(J53:J56) -> 14264.11 | ... L57: =SUM(L53:L56) -> 15576.71
...

Sheet Ration Analysis
B2: ="Historical Financial Statement - " & 'Data Sheet'!B1 -> Historical Financial Statement - GODREJ CONSUMER PRODUCTS LTD
A3: # | B3: Year | C3: ='Data Sheet'!B16 -> 42460 | D3: ='Data Sheet'!C16 -> 42825 | E3: ='Data Sheet'!D16 -> 43190 | F3: ='Data Sheet'!E16 -> 43555 | G3: ='Data Sheet'!F16 -> 43921 | H3: ='Data Sheet'!G16 -> 44286 | I3: ='Data Sheet'!H16 -> 44651 | J3: ='Data Sheet'!I16 -> 45016 | ... L3: ='Data Sheet'!K16 -> 45747 | M3: Trend | N3: Mean | O3: Median
B5: SalesGrowth | D5: =IFERROR(Historical_FS!D7,0) -> -0.091070155 | E5: =IFERROR(Historical_FS!E7,0) -> -0.058849873 | F5: =IFERROR(Historical_FS!F7,0) -> -0.045268044 | G5: =IFERROR(Historical_FS!G7,0) -> 0.040717197 | H5: =IFERROR(Historical_FS!H7,0) -> -0.10135629 | I5: =IFERROR(Historical_FS!I7,0) -> -0.10164786 | J5: =IFERROR(Historical_FS!J7,0) -> -0.078061906 | K5: =IFERROR(Historical_FS!K7,0) -> -0.055344347 | L5: =IFERROR(Historical_FS!L7,0) -> -0.01866991 | N5: =IFERROR(AVERAGE(D5:L5),0) -> -0.056616799 | O5: =IFERROR(MEDIAN(D5:L5),0) -> -0.058849873
B6: EBITDA Growth | D6: =IFERROR((Historical_FS!D18/Historical_FS!C18-1),0) -> 0.15043623 | E6: =IFERROR((Historical_FS!E18/Historical_FS!D18-1),0) -> 0.093191938 | F6: =IFERROR((Historical_FS!F18/Historical_FS!E18-1),0) -> 0.022630013 | G6: =IFERROR((Historical_FS!G18/Historical_FS!F18-1),0) -> 0.010405476 | H6: =IFERROR((Historical_FS!H18/Historical_FS!G18-1),0) -> 0.11399187 | I6: =IFERROR((Historical_FS!I18/Historical_FS!H18-1),0) -> 0.0041346082 | J6: =IFERROR((Historical_FS!J18/Historical_FS!I18-1),0) -> 0.014120987 | K6: =IFERROR((Historical_FS!K18/Historical_FS!J18-1),0) -> 0.21042895 | L6: =IFERROR((Historical_FS!L18/Historical_FS!K18-1),0) -> 0.019507527 | N6: =IFERROR(AVERAGE(D6:L6),0) -> 0.070983067 | O6: =IFERROR(MEDIAN(D6:L6),0) -> 0.022630013
B7: EBIT Growth | D7: =IFERROR((Historical_FS!D27/Historical_FS!C27-1),0) -> 0.13465052 | E7: =IFERROR((Historical_FS!E27/Historical_FS!D27-1),0) -> -0.097573765 | F7: =IFERROR((Historical_FS!F27/Historical_FS!E27-1),0) -> -0.0030999299 | G7: =IFERROR((Historical_FS!G27/Historical_FS!F27-1),0) -> -0.0079575188 | H7: =IFERROR((Historical_FS!H27/Historical_FS!G27-1),0) -> 0.21014433 | I7: =IFERROR((Historical_FS!I27/Historical_FS!H27-1),0) -> 0.24616497 | J7: =IFERROR((Historical_FS!J27/Historical_FS!I27-1),0) -> 0.045456574 | K7: =IFERROR((Historical_FS!K27/Historical_FS!J27-1),0) -> -0.037783243 | L7: =IFERROR((Historical_FS!L27/Historical_FS!K27-1),0) -> 0.70074835 | N7: =IFERROR(AVERAGE(D7:L7),0) -> 0.13230559 | O7: =IFERROR(MEDIAN(D7:L7),0) -> 0.045456574
B8: Net Profit Growth | D8: =IFERROR((Historical_FS!D33/Historical_FS!C33-1),0) -> 0.13526541 | E8: =IFERROR((Historical_FS!E33/Historical_FS!D33-1),0) -> -0.1134066 | F8: =IFERROR((Historical_FS!F33/Historical_FS!E33-1),0) -> 0.18527117 | G8: =IFERROR((Historical_FS!G33/Historical_FS!F33-1),0) -> -0.13275334 | H8: =IFERROR((Historical_FS!H33/Historical_FS!G33-1),0) -> 0.19895433 | I8: =IFERROR((Historical_FS!I33/Historical_FS!H33-1),0) -> 0.26381558 | J8: =IFERROR((Historical_FS!J33/Historical_FS!I33-1),0) -> 0.03784869 | K8: =IFERROR((Historical_FS!K33/Historical_FS!J33-1),0) -> -0.098687639 | L8: =IFERROR((Historical_FS!L33/Historical_FS!K33-1),0) -> 0.7930437 | N8: =IFERROR(AVERAGE(D8:L8),0) -> 0.14103903 | O8: =IFERROR(MEDIAN(D8:L8),0) -> 0.13526541
B9: Dividend Growth | D9: =IFERROR((Historical_FS!D41/Historical_FS!C41-1),0) -> -0.2 | E9: =IFERROR((Historical_FS!E41/Historical_FS!D41-1),0) -> -1 | F9: =IFERROR((Historical_FS!F41/Historical_FS!E41-1),0) -> 0 | G9: =IFERROR((Historical_FS!G41/Historical_FS!F41-1),0) -> 0 | H9: =IFERROR((Historical_FS!H41/Historical_FS!G41-1),0) -> 0 | I9: =IFERROR((Historical_FS!I41/Historical_FS!H41-1),0) -> 0.66666667 | J9: =IFERROR((Historical_FS!J41/Historical_FS!I41-1),0) -> -1 | K9: =IFERROR((Historical_FS!K41/Historical_FS!J41-1),0) -> 0 | L9: =IFERROR((Historical_FS!L41/Historical_FS!K41-1),0) -> 0 | N9: =IFERROR(AVERAGE(D9:L9),0) -> -0.17037037 | O9: =IFERROR(MEDIAN(D9:L9),0) -> 0
B11: Gross Margin | C11: =IFERROR(Historical_FS!C10,0) -> 0.61225825 | D11: =IFERROR(Historical_FS!D10,0) -> 0.59483206 | E11: =IFERROR(Historical_FS!E10,0) -> 0.58407422 | F11: =IFERROR(Historical_FS!F10,0) -> 0.58867848 | G11: =IFERROR(Historical_FS!G10,0) -> 0.5829479 | H11: =IFERROR(Historical_FS!H10,0) -> 0.5944751 | I11: =IFERROR(Historical_FS!I10,0) -> 0.63071885 | J11: =IFERROR(Historical_FS!J10,0) -> 0.631408 | ... L11: =IFERROR(Historical_FS!L10,0) -> 0.57595398 | N11: =IFERROR(AVERAGE(C11:L11),0) -> 0.59728764 | O11: =IFERROR(MEDIAN(C11:L11),0) -> 0.59157679
B12: EBITDA Margin | C12: =IFERROR(Historical_FS!C19,0) -> 0.19674782 | D12: =IFERROR(Historical_FS!D19,0) -> 0.20573247 | E12: =IFERROR(Historical_FS!E19,0) -> 0.21166944 | F12: =IFERROR(Historical_FS!F19,0) -> 0.20666082 | G12: =IFERROR(Historical_FS!G19,0) -> 0.21731344 | H12: =IFERROR(Historical_FS!H19,0) -> 0.21754852 | I12: =IFERROR(Historical_FS!I19,0) -> 0.19624323 | J12: =IFERROR(Historical_FS!J19,0) -> 0.18347894 | ... L12: =IFERROR(Historical_FS!L19,0) -> 0.20989621 | N12: =IFERROR(AVERAGE(C12:L12),0) -> 0.20550878 | O12: =IFERROR(MEDIAN(C12:L12),0) -> 0.20822886
B13: EBIT Margin | C13: =IFERROR((Historical_FS!C18-Historical_FS!C27)/Historical_FS!C6,0) -> -0.25615631 | D13: =IFERROR((Historical_FS!D18-Historical_FS!D27)/Historical_FS!D6,0) -> -0.26135558 | E13: =IFERROR((Historical_FS!E18-Historical_FS!E27)/Historical_FS!E6,0) -> -0.18503711 | F13: =IFERROR((Historical_FS!F18-Historical_FS!F27)/Historical_FS!F6,0) -> -0.1709135 | G13: =IFERROR((Historical_FS!G18-Historical_FS!G27)/Historical_FS!G6,0) -> -0.17250777 | H13: =IFERROR((Historical_FS!H18-Historical_FS!H27)/Historical_FS!H6,0) -> -0.20637759 | I13: =IFERROR((Historical_FS!I18-Historical_FS!I27)/Historical_FS!I6,0) -> -0.27833992 | J13: =IFERROR((Historical_FS!J18-Historical_FS!J27)/Historical_FS!J6,0) -> -0.27394625 | ... L13: =IFERROR((Historical_FS!L18-Historical_FS!L27)/Historical_FS!L6,0) -> -0.48404342 | N13: =IFERROR(AVERAGE(C13:L13),0) -> -0.24946633 | O13: =IFERROR(MEDIAN(C13:L13),0) -> -0.23126695
B14: EBT Margin | C14: =IFERROR(Historical_FS!C28,0) -> 0.45290412 | D14: =IFERROR(Historical_FS!D28,0) -> 0.46708805 | E14: =IFERROR(Historical_FS!E28,0) -> 0.39670655 | F14: =IFERROR(Historical_FS!F28,0) -> 0.37757433 | G14: =IFERROR(Historical_FS!G28,0) -> 0.38982121 | H14: =IFERROR(Historical_FS!H28,0) -> 0.42392611 | I14: =IFERROR(Historical_FS!I28,0) -> 0.47458315 | J14: =IFERROR(Historical_FS!J28,0) -> 0.45742518 | ... L14: =IFERROR(Historical_FS!L28,0) -> 0.69393962 | N14: =IFERROR(AVERAGE(C14:L14),0) -> 0.45497511 | O14: =IFERROR(MEDIAN(C14:L14),0) -> 0.43841512
B15: Net Profit Margin | C15: =IFERROR(Historical_FS!C34,0) -> 0.41301158 | D15: =IFERROR(Historical_FS!D34,0) -> 0.42617699 | E15: =IFERROR(Historical_FS!E34,0) -> 0.35560953 | F15: =IFERROR(Historical_FS!F34,0) -> 0.40241353 | G15: =IFERROR(Historical_FS!G34,0) -> 0.36320176 | H15: =IFERROR(Historical_FS!H34,0) -> 0.39132548 | I15: =IFERROR(Historical_FS!I34,0) -> 0.44429194 | J15: =IFERROR(Historical_FS!J34,0) -> 0.42511285 | ... L15: =IFERROR(Historical_FS!L34,0) -> 0.63688216 | N15: =IFERROR(AVERAGE(C15:L15),0) -> 0.42199796 | O15: =IFERROR(MEDIAN(C15:L15),0) -> 0.40771256
B17: SalesExpenses%Sales | C17: =IFERROR(Historical_FS!C16,0) -> 0.19099394 | D17: =IFERROR(Historical_FS!D16,0) -> 0.19943547 | E17: =IFERROR(Historical_FS!E16,0) -> 0.20425634 | F17: =IFERROR(Historical_FS!F16,0) -> 0.2046607 | G17: =IFERROR(Historical_FS!G16,0) -> 0.19973867 | H17: =IFERROR(Historical_FS!H16,0) -> 0.18797637 | I17: =IFERROR(Historical_FS!I16,0) -> 0.17303792 | J17: =IFERROR(Historical_FS!J16,0) -> 0.18511306 | ... L17: =IFERROR(Historical_FS!L16,0) -> 0.21414981 | N17: =IFERROR(AVERAGE(C17:L17),0) -> 0.19720358 | O17: =IFERROR(MEDIAN(C17:L17),0) -> 0.19958707
B18: Depreciation%Sales | C18: =IFERROR(Historical_FS!C25,0) -> 0.011945802 | D18: =IFERROR(Historical_FS!D25,0) -> 0.015275289 | E18: =IFERROR(Historical_FS!E25,0) -> 0.015809201 | F18: =IFERROR(Historical_FS!F25,0) -> 0.016479969 | G18: =IFERROR(Historical_FS!G25,0) -> 0.019905558 | H18: =IFERROR(Historical_FS!H25,0) -> 0.018483727 | I18: =IFERROR(Historical_FS!I25,0) -> 0.017100151 | J18: =IFERROR(Historical_FS!J25,0) -> 0.017744858 | ... L18: =IFERROR(Historical_FS!L25,0) -> 0.016290398 | N18: =IFERROR(AVERAGE(C18:L18),0) -> 0.016612903 | O18: =IFERROR(MEDIAN(C18:L18),0) -> 0.016787023
B19: OperatingIncome%Sales | C19: =C14 -> 0.45290412 | D19: =D14 -> 0.46708805 | E19: =E14 -> 0.39670655 | F19: =F14 -> 0.37757433 | G19: =G14 -> 0.38982121 | H19: =H14 -> 0.42392611 | I19: =I14 -> 0.47458315 | J19: =J14 -> 0.45742518 | ... L19: =L14 -> 0.69393962 | N19: =IFERROR(AVERAGE(C19:L19),0) -> 0.45497511 | O19: =IFERROR(MEDIAN(C19:L19),0) -> 0.43841512
B21: Return on Capital Employed | C21: =IFERROR((Historical_FS!C18-Historical_FS!C24)/SUM(Historical_FS!C47:C49),0) -> 0.2174815 | D21: =IFERROR((Historical_FS!D18-Historical_FS!D24)/SUM(Historical_FS!D47:D49),0) -> 0.18974124 | E21: =IFERROR((Historical_FS!E18-Historical_FS!E24)/SUM(Historical_FS!E47:E49),0) -> 0.19749577 | F21: =IFERROR((Historical_FS!F18-Historical_FS!F24)/SUM(Historical_FS!F47:F49),0) -> 0.18420467 | G21: =IFERROR((Historical_FS!G18-Historical_FS!G24)/SUM(Historical_FS!G47:G49),0) -> 0.17052329 | H21: =IFERROR((Historical_FS!H18-Historical_FS!H24)/SUM(Historical_FS!H47:H49),0) -> 0.19423474 | I21: =IFERROR((Historical_FS!I18-Historical_FS!I24)/SUM(Historical_FS!I47:I49),0) -> 0.16585258 | J21: =IFERROR((Historical_FS!J18-Historical_FS!J24)/SUM(Historical_FS!J47:J49),0) -> 0.14787846 | ... L21: =IFERROR((Historical_FS!L18-Historical_FS!L24)/SUM(Historical_FS!L47:L49),0) -> 0.17372181 | N21: =IFERROR(AVERAGE(C21:L21),0) -> 0.18128299 | O21: =IFERROR(MEDIAN(C21:L21),0) -> 0.17896324
B22: Retained Earnings% | C22: =IFERROR(Historical_FS!C44,0) -> 0.70619345 | D22: =IFERROR(Historical_FS!D44,0) -> 0.79293984 | E22: =IFERROR(Historical_FS!E44,0) -> 1 | F22: =IFERROR(Historical_FS!F44,0) -> 1 | G22: =IFERROR(Historical_FS!G44,0) -> 1 | H22: =IFERROR(Historical_FS!H44,0) -> 0.64451385 | I22: =IFERROR(Historical_FS!I44,0) -> 0.5311082 | J22: =IFERROR(Historical_FS!J44,0) -> 0 | ... L22: =IFERROR(Historical_FS!L44,0) -> 0 | N22: =IFERROR(AVERAGE(C22:L22),0) -> 0.56747553 | O22: =IFERROR(MEDIAN(C22:L22),0) -> 0.67535365
B23: Return on Equity% | C23: =IFERROR((Historical_FS!C33)/(SUM(Historical_FS!C47:C49)),0) -> 0.48604654 | D23: =IFERROR((Historical_FS!D33)/(SUM(Historical_FS!D47:D49)),0) -> 0.42457497 | E23: =IFERROR((Historical_FS!E33)/(SUM(Historical_FS!E47:E49)),0) -> 0.35857905 | F23: =IFERROR((Historical_FS!F33)/(SUM(Historical_FS!F47:F49)),0) -> 0.38976821 | G23: =IFERROR((Historical_FS!G33)/(SUM(Historical_FS!G47:G49)),0) -> 0.31373803 | H23: =IFERROR((Historical_FS!H33)/(SUM(Historical_FS!H47:H49)),0) -> 0.38183046 | I23: =IFERROR((Historical_FS!I33)/(SUM(Historical_FS!I47:I49)),0) -> 0.41133024 | J23: =IFERROR((Historical_FS!J33)/(SUM(Historical_FS!J47:J49)),0) -> 0.37931266 | ... L23: =IFERROR((Historical_FS!L33)/(SUM(Historical_FS!L47:L49)),0) -> 0.57147212 | N23: =IFERROR(AVERAGE(C23:L23),0) -> 0.40391486 | O23: =IFERROR(MEDIAN(C23:L23),0) -> 0.38579933 | P23: EAES/SHF
B24: Self Sustained Growth Rate | C24: =IFERROR((1-Historical_FS!C42)*Historical_FS!C44,0) -> 0.49870919 | D24: =IFERROR((1-Historical_FS!D42)*Historical_FS!D44,0) -> 0.62875359 | E24: =IFERROR((1-Historical_FS!E42)*Historical_FS!E44,0) -> 1 | F24: =IFERROR((1-Historical_FS!F42)*Historical_FS!F44,0) -> 1 | G24: =IFERROR((1-Historical_FS!G42)*Historical_FS!G44,0) -> 1 | H24: =IFERROR((1-Historical_FS!H42)*Historical_FS!H44,0) -> 0.41539811 | I24: =IFERROR((1-Historical_FS!I42)*Historical_FS!I44,0) -> 0.28207592 | J24: =IFERROR((1-Historical_FS!J42)*Historical_FS!J44,0) -> 0 | ... L24: =IFERROR((1-Historical_FS!L42)*Historical_FS!L44,0) -> 0 | N24: =IFERROR(AVERAGE(C24:L24),0) -> 0.48249368 | O24: =IFERROR(MEDIAN(C24:L24),0) -> 0.45705365 | P24: g=b*r (b=1-divident payout ration , r = returm on equity)
B25: Interest Coverage Ratio | C25: =(Historical_FS!C18-Historical_FS!C24)/Historical_FS!C21 -> -5.9408869 | D25: =(Historical_FS!D18-Historical_FS!D24)/Historical_FS!D21 -> 23.170648 | E25: =(Historical_FS!E18-Historical_FS!E24)/Historical_FS!E21 -> 6.8085287 | F25: =(Historical_FS!F18-Historical_FS!F24)/Historical_FS!F21 -> 5.4195055 | G25: =(Historical_FS!G18-Historical_FS!G24)/Historical_FS!G21 -> 61.025265 | H25: =(Historical_FS!H18-Historical_FS!H24)/Historical_FS!H21 -> 97.142035 | I25: =(Historical_FS!I18-Historical_FS!I24)/Historical_FS!I21 -> 28.09825 | J25: =(Historical_FS!J18-Historical_FS!J24)/Historical_FS!J21 -> 19.308049 | ... L25: =(Historical_FS!L18-Historical_FS!L24)/Historical_FS!L21 -> 11.03882 | N25: =IFERROR(AVERAGE(C25:L25),0) -> 24.484029 | O25: =IFERROR(MEDIAN(C25:L25),0) -> 15.173435 | P25: ebt/interets expneses
B27: Debtor Turnover Ratio | C27: =IFERROR(Historical_FS!C6/Historical_FS!C59,0) -> 7.534709 | D27: =IFERROR(Historical_FS!D6/Historical_FS!D59,0) -> 9.0089916 | E27: =IFERROR(Historical_FS!E6/Historical_FS!E59,0) -> 7.9064071 | F27: =IFERROR(Historical_FS!F6/Historical_FS!F59,0) -> 7.9776781 | G27: =IFERROR(Historical_FS!G6/Historical_FS!G59,0) -> 8.5640959 | H27: =IFERROR(Historical_FS!H6/Historical_FS!H59,0) -> 10.979214 | I27: =IFERROR(Historical_FS!I6/Historical_FS!I59,0) -> 10.997295 | J27: =IFERROR(Historical_FS!J6/Historical_FS!J59,0) -> 10.693153 | ... L27: =IFERROR(Historical_FS!L6/Historical_FS!L59,0) -> 7.8962416 | N27: =IFERROR(AVERAGE(C27:L27),0) -> 9.0738705 | O27: =IFERROR(MEDIAN(C27:L27),0) -> 8.7865437
B28: Creditor Turnover Ratio | C28: =IFERROR(Historical_FS!C6/Historical_FS!C50,0) -> 3.3419343 | D28: =IFERROR(Historical_FS!D6/Historical_FS!D50,0) -> 2.5479701 | E28: =IFERROR(Historical_FS!E6/Historical_FS!E50,0) -> 2.4030489 | F28: =IFERROR(Historical_FS!F6/Historical_FS!F50,0) -> 2.994368 | G28: =IFERROR(Historical_FS!G6/Historical_FS!G50,0) -> 2.9089948 | H28: =IFERROR(Historical_FS!H6/Historical_FS!H50,0) -> 3.7500578 | I28: =IFERROR(Historical_FS!I6/Historical_FS!I50,0) -> 4.3505147 | J28: =IFERROR(Historical_FS!J6/Historical_FS!J50,0) -> 5.2978854 | ... L28: =IFERROR(Historical_FS!L6/Historical_FS!L50,0) -> 4.3672536 | N28: =IFERROR(AVERAGE(C28:L28),0) -> 3.7444101 | O28: =IFERROR(MEDIAN(C28:L28),0) -> 3.545996
B29: Inventory Turnover | C29: =IFERROR(Historical_FS!C6/Historical_FS!C60,0) -> 6.4453014 | D29: =IFERROR(Historical_FS!D6/Historical_FS!D60,0) -> 6.5613522 | E29: =IFERROR(Historical_FS!E6/Historical_FS!E60,0) -> 6.2415574 | F29: =IFERROR(Historical_FS!F6/Historical_FS!F60,0) -> 6.6177378 | G29: =IFERROR(Historical_FS!G6/Historical_FS!G60,0) -> 5.8192024 | H29: =IFERROR(Historical_FS!H6/Historical_FS!H60,0) -> 6.4259985 | I29: =IFERROR(Historical_FS!I6/Historical_FS!I60,0) -> 5.7640209 | J29: =IFERROR(Historical_FS!J6/Historical_FS!J60,0) -> 8.6627655 | ... L29: =IFERROR(Historical_FS!L6/Historical_FS!L60,0) -> 10.12568 | N29: =IFERROR(AVERAGE(C29:L29),0) -> 7.3754881 | O29: =IFERROR(MEDIAN(C29:L29),0) -> 6.5033268
B30: Fixed Asset Turnover | C30: =IFERROR(Historical_FS!C6/Historical_FS!C53,0) -> 1.4202154 | D30: =IFERROR(Historical_FS!D6/Historical_FS!D53,0) -> 1.1466085 | E30: =IFERROR(Historical_FS!E6/Historical_FS!E53,0) -> 1.1842971 | F30: =IFERROR(Historical_FS!F6/Historical_FS!F53,0) -> 1.1896229 | G30: =IFERROR(Historical_FS!G6/Historical_FS!G53,0) -> 1.0735966 | H30: =IFERROR(Historical_FS!H6/Historical_FS!H53,0) -> 1.238507 | I30: =IFERROR(Historical_FS!I6/Historical_FS!I53,0) -> 1.3316087 | J30: =IFERROR(Historical_FS!J6/Historical_FS!J53,0) -> 1.3404898 | ... L30: =IFERROR(Historical_FS!L6/Historical_FS!L53,0) -> 1.345451 | N30: =IFERROR(AVERAGE(C30:L30),0) -> 1.2620568 | O30: =IFERROR(MEDIAN(C30:L30),0) -> 1.2850578
B31: Capital Turnover Ratio | C31: =IFERROR(Historical_FS!C6/Historical_FS!C47,0) -> 247.39736 | D31: =IFERROR(Historical_FS!D6/Historical_FS!D47,0) -> 272.1054 | E31: =IFERROR(Historical_FS!E6/Historical_FS!E47,0) -> 144.53882 | F31: =IFERROR(Historical_FS!F6/Historical_FS!F47,0) -> 100.90335 | G31: =IFERROR(Historical_FS!G6/Historical_FS!G47,0) -> 96.946102 | H31: =IFERROR(Historical_FS!H6/Historical_FS!H47,0) -> 107.85936 | I31: =IFERROR(Historical_FS!I6/Historical_FS!I47,0) -> 120.05183 | J31: =IFERROR(Historical_FS!J6/Historical_FS!J47,0) -> 130.20407 | ... L31: =IFERROR(Historical_FS!L6/Historical_FS!L47,0) -> 140.41339 | N31: =IFERROR(AVERAGE(C31:L31),0) -> 149.82385 | O31: =IFERROR(MEDIAN(C31:L31),0) -> 134.01145
B33: Debtor Days | C33: =IFERROR(365/C27,0) -> 48.442481 | D33: =IFERROR(365/D27,0) -> 40.515078 | E33: =IFERROR(365/E27,0) -> 46.165091 | F33: =IFERROR(365/F27,0) -> 45.752661 | G33: =IFERROR(365/G27,0) -> 42.619794 | H33: =IFERROR(365/H27,0) -> 33.24464 | I33: =IFERROR(365/I27,0) -> 33.189981 | J33: =IFERROR(365/J27,0) -> 34.133991 | ... L33: =IFERROR(365/L27,0) -> 46.224523 | N33: =IFERROR(AVERAGE(C33:L33),0) -> 41.00446 | O33: =IFERROR(MEDIAN(C33:L33),0) -> 41.567436
B34: Payable Days | C34: =IFERROR(365/C28,0) -> 109.21819 | D34: =IFERROR(365/D28,0) -> 143.25129 | E34: =IFERROR(365/E28,0) -> 151.89038 | F34: =IFERROR(365/F28,0) -> 121.89551 | G34: =IFERROR(365/G28,0) -> 125.47289 | H34: =IFERROR(365/H28,0) -> 97.331833 | I34: =IFERROR(365/I28,0) -> 83.898118 | J34: =IFERROR(365/J28,0) -> 68.895413 | ... L34: =IFERROR(365/L28,0) -> 83.576553 | N34: =IFERROR(AVERAGE(C34:L34),0) -> 105.20108 | O34: =IFERROR(MEDIAN(C34:L34),0) -> 103.27501
B35: Inventory Days | C35: =IFERROR(365/C29,0) -> 56.630401 | D35: =IFERROR(365/D29,0) -> 55.628777 | E35: =IFERROR(365/E29,0) -> 58.478994 | F35: =IFERROR(365/F29,0) -> 55.154799 | G35: =IFERROR(365/G29,0) -> 62.723372 | H35: =IFERROR(365/H29,0) -> 56.800511 | I35: =IFERROR(365/I29,0) -> 63.32385 | J35: =IFERROR(365/J29,0) -> 42.134351 | ... L35: =IFERROR(365/L29,0) -> 36.046961 | N35: =IFERROR(AVERAGE(C35:L35),0) -> 51.98308 | O35: =IFERROR(MEDIAN(C35:L35),0) -> 56.129589
B36: Cash Conversion Cycle (in days)
B38: CFO/Sales | C38: =IFERROR(Historical_FS!C80/Historical_FS!C6,0) -> 0.10054749 | D38: =IFERROR(Historical_FS!D80/Historical_FS!D6,0) -> 0.2006925 | E38: =IFERROR(Historical_FS!E80/Historical_FS!E6,0) -> 0.17507106 | F38: =IFERROR(Historical_FS!F80/Historical_FS!F6,0) -> 0.16753374 | G38: =IFERROR(Historical_FS!G80/Historical_FS!G6,0) -> 0.16022924 | H38: =IFERROR(Historical_FS!H80/Historical_FS!H6,0) -> 0.18406655 | I38: =IFERROR(Historical_FS!I80/Historical_FS!I6,0) -> 0.11811184 | J38: =IFERROR(Historical_FS!J80/Historical_FS!J6,0) -> 0.16161046 | ... L38: =IFERROR(Historical_FS!L80/Historical_FS!L6,0) -> 0.17940323 | N38: =IFERROR(AVERAGE(C38:L38),0) -> 0.15941151 | O38: =IFERROR(MEDIAN(C38:L38),0) -> 0.1645721
B39: CFO/Total Assets | C39: =IFERROR(Historical_FS!C80/Historical_FS!C64,0) -> 0.087511391 | D39: =IFERROR(Historical_FS!D80/Historical_FS!D64,0) -> 0.14373756 | E39: =IFERROR(Historical_FS!E80/Historical_FS!E64,0) -> 0.1243529 | F39: =IFERROR(Historical_FS!F80/Historical_FS!F64,0) -> 0.12260928 | G39: =IFERROR(Historical_FS!G80/Historical_FS!G64,0) -> 0.10671842 | H39: =IFERROR(Historical_FS!H80/Historical_FS!H64,0) -> 0.14251825 | I39: =IFERROR(Historical_FS!I80/Historical_FS!I64,0) -> 0.090162242 | J39: =IFERROR(Historical_FS!J80/Historical_FS!J64,0) -> 0.12341388 | ... L39: =IFERROR(Historical_FS!L80/Historical_FS!L64,0) -> 0.13354061 | N39: =IFERROR(AVERAGE(C39:L39),0) -> 0.1187113 | O39: =IFERROR(MEDIAN(C39:L39),0) -> 0.12301158
B40: CFO/Total Debt | C40: =IFERROR(Historical_FS!C80/Historical_FS!C59,0) -> 0.75759609 | D40: =IFERROR(Historical_FS!D80/Historical_FS!D59,0) -> 1.808037 | E40: =IFERROR(Historical_FS!E80/Historical_FS!E59,0) -> 1.3841831 | F40: =IFERROR(Historical_FS!F80/Historical_FS!F59,0) -> 1.3365303 | G40: =IFERROR(Historical_FS!G80/Historical_FS!G59,0) -> 1.3722186 | H40: =IFERROR(Historical_FS!H80/Historical_FS!H59,0) -> 2.0209059 | I40: =IFERROR(Historical_FS!I80/Historical_FS!I59,0) -> 1.2989107 | J40: =IFERROR(Historical_FS!J80/Historical_FS!J59,0) -> 1.7281254 | ... L40: =IFERROR(Historical_FS!L80/Historical_FS!L59,0) -> 1.4166112 | N40: =IFERROR(AVERAGE(C40:L40),0) -> 1.4471328 | O40: =IFERROR(MEDIAN(C40:L40),0) -> 1.3782008

Sheet Data>

Sheet Data Sheet
A1: COMPANY NAME | B1: GODREJ CONSUMER PRODUCTS LTD | E1: =IF(B2<>B3, "A NEW VERSION OF THE WORKSHEET IS AVAILABLE", "")
A2: LATEST VERSION | B2: 2.1 | E2: PLEASE DO NOT MAKE ANY CHANGES TO THIS SHEET
A3: CURRENT VERSION | B3: 2.1
A5: META
A6: Number of shares | B6: =IF(B9>0, B9/B8, 0) -> 102.32446
A7: Face Value | B7: 1
A8: Current Price | B8: 1017.6
A9: Market Capitalization | B9: 104125.37
A15: PROFIT & LOSS
A16: Report Date | B16: 42460 | C16: 42825 | D16: 43190 | E16: 43555 | F16: 43921 | G16: 44286 | H16: 44651 | I16: 45016 | J16: 45382 | K16: 45747
A17: Sales | B17: 8423.88 | C17: 9267.91 | D17: 9847.43 | E17: 10314.34 | F17: 9910.8 | G17: 11028.62 | H17: 12276.5 | I17: 13315.97 | J17: 14096.11 | K17: 14364.29
A18: Raw Material Cost | B18: 3959.14 | C18: 4265.85 | D18: 4218.36 | E18: 4399.79 | F18: 4434.83 | G18: 4971.77 | H18: 6136.63 | I18: 6489.85 | J18: 6333.43 | K18: 6594.23
A19: Change in Inventory | B19: 91.9 | C19: 133.33 | D19: -56 | E19: -154.54 | F19: 173.15 | G19: 42.35 | H19: 61.54 | I19: -212.94 | J19: 13.13 | K19: 58.12
A20: Power and Fuel | B20: 109.99 | C20: 89.02 | D20: 101.11 | E20: 119.29 | F20: 118.29 | G20: 106.23 | H20: 133.49 | I20: 154.63 | J20: 150.85 | K20: 138.37
A21: Other Mfr. Exp | B21: 236.23 | C21: 302.85 | D21: 318.75 | E21: 329.8 | F21: 378.69 | G21: 397.25 | H21: 430.3 | I21: 438.91 | J21: 420.43 | K21: 449.91
A22: Employee Cost | B22: 944.13 | C22: 988.46 | D22: 1057.41 | E22: 1068.41 | F22: 1018.82 | G22: 1123.34 | H22: 1104.14 | I22: 1111.48 | J22: 1249.34 | K22: 1148.78
A23: Selling and admin | B23: 1464.98 | C23: 1649.39 | D23: 1775.76 | E23: 1888.86 | F23: 1770.13 | G23: 1808.73 | H23: 1836.49 | I23: 2144.44 | J23: 2639.66 | K23: 4241.27
A24: Other Expenses | B24: 143.93 | C24: 198.96 | D24: 235.64 | E24: 222.08 | F24: 209.44 | G24: 264.39 | H24: 287.81 | I24: 320.52 | J24: 358.21 | K24: -1165.16
A25: Other Income | B25: -262.04 | C25: 76.18 | D25: 283.28 | E25: 361.95 | F25: 32.06 | G25: 22.6 | H25: 78.27 | I25: 114.3 | J25: -2208.56 | K25: 251.93
A26: Depreciation | B26: 100.63 | C26: 141.57 | D26: 155.68 | E26: 169.98 | F26: 197.28 | G26: 203.85 | H26: 209.93 | I26: 236.29 | J26: 240.96 | K26: 234
A27: Interest | B27: 128.04 | C27: 154.19 | D27: 173.12 | E27: 238.21 | F27: 228.13 | G27: 137.65 | H27: 122.26 | I27: 188.48 | J27: 309.57 | K27: 361.05
... A30: Net profit | B30: 827.61 | C30: 1304.08 | D30: 1634.18 | E30: 2341.53 | F30: 1496.58 | G30: 1720.82 | H30: 1783.39 | I30: 1702.46 | J30: -560.55 | K30: 1852.3
A31: Dividend Amount | B31: 195.79 | C31: 510.9 | D31: 681.3 | E31: 1022.2 | F31: 817.84 | J31: 1534.2 | K31: 2557.5
A40: Quarters
A41: Report Date | B41: 45199 | C41: 45291 | D41: 45382 | E41: 45473 | F41: 45565 | G41: 45657 | H41: 45747 | I41: 45838 | J41: 45930 | K41: 46022
A42: Sales | B42: 3601.95 | C42: 3659.64 | D42: 3385.61 | E42: 3331.58 | F42: 3666.33 | G42: 3768.43 | H42: 3597.95 | I42: 3661.86 | J42: 3825.09 | K42: 4099.12
A43: Expenses | B43: 2897.78 | C43: 2818.92 | D43: 2629.89 | E43: 2607.15 | F43: 2906.69 | G43: 3012.49 | H43: 2838.73 | I43: 2967.3 | J43: 3091.76 | K43: 3218.68
A44: Other Income | B44: 53.39 | C44: 63.19 | D44: -2311.81 | E44: 56.81 | F44: 80.21 | G44: 77.36 | H44: 42.3 | I44: 64.98 | J44: 33.19 | K44: -35.11
A45: Depreciation | B45: 60.88 | C45: 53.88 | D45: 49.91 | E45: 49.46 | F45: 50.1 | G45: 61.89 | H45: 72.55 | I45: 59.35 | J45: 65.64 | K45: 66.41
A46: Interest | B46: 77.31 | C46: 66.59 | D46: 78.47 | E46: 87.75 | F46: 83.09 | G46: 89.71 | H46: 89.56 | I46: 86.49 | J46: 75.87 | K46: 78.94
A47: Profit before tax | B47: 619.37 | C47: 783.44 | D47: -1684.47 | E47: 644.03 | F47: 706.66 | G47: 681.7 | H47: 639.41 | I47: 613.7 | J47: 625.01 | K47: 699.98
A48: Tax | B48: 186.6 | C48: 202.38 | D48: 208.74 | E48: 193.34 | F48: 215.35 | G48: 183.39 | H48: 227.51 | I48: 161.25 | J48: 165.67 | K48: 202.07
A49: Net profit | B49: 432.77 | C49: 581.06 | D49: -1893.21 | E49: 450.69 | F49: 491.31 | G49: 498.31 | H49: 411.9 | I49: 452.45 | J49: 459.34 | K49: 497.91
A50: Operating Profit | B50: 704.17 | C50: 840.72 | D50: 755.72 | E50: 724.43 | F50: 759.64 | G50: 755.94 | H50: 759.22 | I50: 694.56 | J50: 733.33 | K50: 880.44
A55: BALANCE SHEET
A56: Report Date | B56: 42460 | C56: 42825 | D56: 43190 | E56: 43555 | F56: 43921 | G56: 44286 | H56: 44651 | I56: 45016 | J56: 45382 | K56: 45747
A57: Equity Share Capital | B57: 34.05 | C57: 34.06 | D57: 68.13 | E57: 102.22 | F57: 102.23 | G57: 102.25 | H57: 102.26 | I57: 102.27 | J57: 102.28 | K57: 102.3
A58: Reserves | B58: 4232.91 | C58: 5267.89 | D58: 6190.18 | E58: 7164.7 | F58: 7796.13 | G58: 9336.65 | H58: 11453.67 | I58: 13691.96 | J58: 12496.29 | K58: 11896.91
A59: Borrowings | B59: 2891.12 | C59: 4000.93 | D59: 3507.57 | E59: 3382.05 | F59: 3574.97 | G59: 1863.97 | H59: 1704.34 | I59: 1129.58 | J59: 3222.2 | K59: 4009.2
A60: Other Liabilities | B60: 2520.66 | C60: 3637.37 | D60: 4097.89 | E60: 3444.58 | F60: 3406.95 | G60: 2940.92 | H60: 2821.85 | I60: 2513.45 | J60: 2571.31 | K60: 3289.09
...

Sheet cashflow data set 
C3: 41699 | D3: 42064 | E3: 42430 | F3: 42795 | G3: 43160 | H3: 43525 | I3: 43891 | J3: 44256 | K3: 44621 | L3: 44986 | M3: 45352 | N3: 45717
B4: Cash from Operating Activity - | C4: 1116 | D4: 1027 | E4: 847 | F4: 1860 | G4: 1723 | H4: 1729 | I4: 1588 | J4: 2030 | K4: 1451 | L4: 2151 | M4: 2070 | N4: 2577
B5: Profit from operations | C5: 1168 | D5: 1397 | E5: 1669 | F5: 1947 | G5: 2147 | H5: 2181 | I5: 2185 | J5: 2472 | K5: 2434 | L5: 2476 | M5: 2900 | N5: 3012
B6: Receivables | C6: 13 | D6: -81 | E6: -323 | F6: 166 | G6: -245 | H6: -174 | I6: 130 | J6: 81 | K6: -89 | L6: -165 | M6: -479 | N6: -305
B7: Inventory | C7: -35 | D7: 26 | E7: -235 | F7: 46 | G7: -165 | H7: -20 | I7: -169 | J7: -70 | K7: -384 | L7: 555 | M7: -71 | N7: -159
B8: Payables | C8: 0 | D8: 0 | E8: 17 | F8: 196 | G8: 613 | H8: 274 | I8: -95 | J8: -473 | K8: 83 | L8: -370 | M8: 91 | N8: 514
B9: Loans Advances | C9: -15 | D9: 8 | E9: 1 | F9: -3 | G9: 1 | H9: -1 | I9: -3 | J9: 1 | K9: 0 | L9: 0 | M9: 0 | N9: 0
B10: Other WC items | C10: 224 | D10: -39 | E10: 75 | F10: -65 | G10: -219 | H10: -79 | I10: -116 | J10: 416 | K10: -146 | L10: 74 | M10: 3 | N10: -15
B11: Working capital changes | C11: 186 | D11: -87 | E11: 465 | F11: 341 | G11: -16 | H11: 1 | I11: -253 | J11: -45 | K11: -536 | L11: 93 | M11: -456 | N11: 35
B12: Direct taxes | C12: -238 | D12: -257 | E12: -336 | F12: -407 | G12: -393 | H12: -435 | I12: -344 | J12: -397 | K12: -448 | L12: -418 | M12: -374 | N12: -470
B13: Other operating items | C13: 0 | D13: 0 | E13: 0 | F13: -20 | G13: -15 | H13: -18 | I13: 0 | J13: 0 | K13: 0 | L13: 0 | M13: 0 | N13: 0
B14: Exceptional CF items | C14: -1 | D14: -26 | E14: -21 | F14: 0 | G14: 0 | H14: 0 | I14: 0 | J14: 0 | K14: 0 | L14: 0 | M14: 0 | N14: 0
B15: Cash from Investing Activity - | C15: -494 | D15: -1236 | E15: -622 | F15: -2243 | G15: -336 | H15: 274 | I15: -552 | J15: -292 | K15: -844 | L15: -1754 | M15: -3435 | N15: -343
... B36: Net Cash Flow | C36: 1 | D36: -221 | E36: 23 | F36: 282 | G36: 3 | H36: -36 | I36: -259 | J36: -79 | K36: 227 | L36: -398 | M36: 41 | N36: 52
